Workbook

Sheet Test Cases
A1: Test Case ID | B1: Category | C1: Test Case | D1: Expected Result | E1: Actual Result | F1: Test Result | G1: Test Result Criteria | H1: Requirement Traceability | I1: Rubric Mapping | J1: Test Result Reasoning | K1: What should be fixed in the code | L1: Severity if failed | M1: Execution | N1: Change from v3 | O1: Evidence to capture | P1: Rubric primary | Q1: Rubric supporting
A2: TC-001 | B2: Individual-paper retrieval | C2: What is the main idea of the sketching approach to program synthesis? | D2: Answer explains sketching as a partial-program technique: the programmer writes a sketch with holes/unknowns, and a solver fills them. Draws on aplas_Solar-Lezama09 and/or pldi_Solar-LezamaRBE05. Sources line names one or both of these papers. | G2: Pass: answer mentions a hole/unknown/template concept and names a real sketching paper in Sources. Fail: answer is generic, names no source, or cites an unrelated paper. | H2: Spec S4/S6.1 - individual-paper retrieval; Design S4-5 - retrieval and citation | I2: Primary: P5 Retrieval approach. Supporting: P4 System behavior; P6 Workflow; P7 Evaluation evidence. | L2: Blocking | M2: Harness: chat window | N2: Carried from v3 | O2: Answer plus Sources line for a single-paper question | P2: P5 | Q2: P4 P6 P7
A3: TC-002 | B3: Individual-paper retrieval | C3: What does the CRUXEval benchmark measure? | D3: Answer states CRUXEval evaluates code reasoning via input/output prediction and execution, citing icml_GuRLSS024. | G3: Pass: answer mentions input/output prediction or execution, and Sources line names the CRUXEval paper. Fail: benchmark purpose is wrong or unsourced. | H3: Spec S6.1 - individual-paper retrieval | I3: Primary: P5 Retrieval approach. Supporting: P4 System behavior; P7 Evaluation evidence. | L3: Blocking | M3: Harness: chat window | N3: Carried from v3 | O3: Example answer for the retrieval section | P3: P5 | Q3: P4 P7
A4: TC-003 | B4: Individual-paper retrieval | C4: What does the LINC paper do with logical reasoning? | D4: Answer describes LINC's neurosymbolic approach combining an LLM with a symbolic first-order logic theorem prover, citing emnlp_OlaussonGLZSTL23. | G4: Pass: answer mentions first-order logic or a theorem prover (for example Prover9) AND the Sources line names the LINC paper (emnlp_OlaussonGLZSTL23). Fail: LINC is described only as 'neurosymbolic' or 'scalable logical reasoning' with no mechanism, which is the run-1 failure. | H4: Spec S6.1 - individual-paper retrieval | I4: Primary: P5 Retrieval approach. Supporting: P7 Evaluation evidence. | L4: Should-fix | M4: Harness: chat window | N4: Carried from v3 | O4: Retest: LINC mechanism named | P4: P5 | Q4: P7
A5: TC-004 | B5: Individual-paper retrieval | C5: What is adaptive concretization? | D5: Answer explains it as a technique for parallel program synthesis that concretizes parts of the search space (e.g. via parallel/randomized SAT solving), citing cav_JeonQSF15. | G5: Pass: answer mentions concretization and parallel/SAT-based search, cites the right paper. Fail: confuses this with a different synthesis technique. | H5: Spec S6.1 - individual-paper retrieval | I5: Primary: P5 Retrieval approach. Supporting: P7 Evaluation evidence. | L5: Should-fix | M5: Harness: chat window | N5: Carried from v3 | O5: Example answer for the retrieval section | P5: P5 | Q5: P7
A6: TC-005 | B6: Individual-paper retrieval | C6: What is the Euler system for? | D6: Answer identifies Euler as a system for numerical optimization of programs, citing cav_ChaudhuriS12. | G6: Pass: answer mentions numerical optimization and cites Euler's paper. Fail: wrong system purpose or no citation. | H6: Spec S6.1 - individual-paper retrieval | I6: Primary: P5 Retrieval approach. Supporting: P7 Evaluation evidence. | L6: Should-fix | M6: Harness: chat window | N6: Carried from v3 | O6: Example answer for the retrieval section | P6: P5 | Q6: P7
A7: TC-006 | B7: Individual-paper retrieval | C7: What does the self-repair paper conclude about fixing code generation errors? | D7: Answer summarizes the finding that self-repair gives inconsistent gains and is not a reliable fix across models, citing iclr_OlaussonIW0S24 ("Is Self-Repair a Silver Bullet for Code Generation?"). | G7: Pass: answer reflects a qualified/skeptical conclusion, not a blanket "self-repair works" claim, and cites the right paper. Fail: overstates self-repair's effectiveness or misattributes the source. | H7: Spec S6.1/S6.6 - retrieval with accurate conclusion, not overclaiming | I7: Primary: P4 System behavior. Supporting: P7 Evaluation evidence; P5 Retrieval approach. | L7: Blocking | M7: Harness: chat window | N7: Carried from v3 | O7: Conclusion stated without overclaiming | P7: P4 | Q7: P7 P5
A8: TC-007 | B8: Individual-paper retrieval | C8: How do verifiers act as oracles in CEGIS? | D8: Answer explains the counterexample-guided loop: a verifier checks a candidate program and returns a counterexample when it fails, which drives the next synthesis attempt. The question is not blocked or altered. | G8: Pass: answer describes the verify / counterexample loop and is not a refusal. Fail: the answer says the documents do not contain the information (the run-1 failure), or the question is blocked or visibly altered. The sanitizer false-positive aspect is isolated in TC-042 so this case measures retrieval only. | H8: Spec 6.1; Architecture 10 (retrieval relevance); Design 4-5 | I8: Primary: P9a Trade-offs: retrieval strategies. Supporting: P5 Retrieval approach; P7 Evaluation evidence. | L8: Should-fix | M8: Harness: chat window | N8: Carried from v3 | O8: Retest: verifier phrasing finds the CEGIS content | P8: P9a | Q8: P5 P7
A9: TC-008 | B9: Individual-paper retrieval | C9: What year was the sketching paper by Solar-Lezama and Bodik published, and what conference? | D9: Answer names PLDI 2005 for "Programming by Sketching for Bit-Streaming Programs" (pldi_Solar-LezamaRBE05), consistent with the resolved year metadata. | G9: Pass: year and venue are correct and match the resolved year field, not a guessed or hallucinated date. Fail: wrong year/venue or a date not grounded in the corpus. | H9: Design S4 - publication-year resolution | I9: Primary: P4 System behavior. Supporting: P5 Retrieval approach. | L9: Should-fix | M9: Harness: chat window | N9: Retest (failed in run 3) | O9: Example answer for the retrieval section | P9: P4 | Q9: P5
A10: TC-009 | B10: Individual-paper retrieval | C10: What does this collection say about AlphaFold and protein structure prediction? | D10: The collection has no content on AlphaFold or protein folding (0 mentions of either across all 153 documents). The answer says so plainly instead of inventing content. If the Sources line lists anything, the answer must not claim those papers discuss protein structure. | G10: Pass: answer states the collection does not cover this, with no invented AlphaFold or protein-folding claims. Fail: the answer describes protein-structure content, or cites a paper as if it supported such content. (v1 asked about quantum computing; a corpus scan showed the collection does contain quantum content, so that oracle was wrong. The quantum question is now a positive control in TC-075.) | H10: Spec 1 and 6.6 (honest non-answer); Test Strategy 8.1 bullet 3 | I10: Primary: P4 System behavior. Supporting: P10 Remaining limitations; P7 Evaluation evidence. | L10: Blocking | M10: Harness: chat window | N10: Carried from v3 | O10: Honest non-answer for a topic that is absent | P10: P4 | Q10: P10 P7
A11: TC-010 | B11: Individual-paper retrieval | C11: What is the main idea of the main idea of the approach the approach uses? | D11: A deliberately malformed/repetitive question. Answer either asks for clarification or makes a reasonable best-effort attempt without crashing or returning an empty response. | G11: Pass: system returns a coherent response or a clarification request, no exception/crash. Fail: unhandled error, blank output, or a stack trace surfaces to the user. | H11: Design S10 - error handling for malformed input | I11: Primary: P4 System behavior. Supporting: P9e Trade-offs: operational considerations. | L11: Noted | M11: Harness: chat window | N11: Carried from v3 | O11: Example answer for the retrieval section | P11: P4 | Q11: P9e
A12: TC-011 | B12: Cross-paper comparison | C12: Compare LiveCodeBench and CRUXEval: how do they differ in what they test? | D12: Answer addresses each benchmark separately (LiveCodeBench: holistic, contamination-free code evaluation; CRUXEval: input/output prediction and execution reasoning) then states the difference, citing both iclr_JainHGLYZWSSS25 and icml_GuRLSS024. | G12: Pass: both papers appear in Sources, answer is structured per-paper rather than blended, and the stated difference is accurate. Fail: only one paper is used, or the answer blends both into an undifferentiated summary. | H12: Spec S6.2/S6.5 - cross-paper comparison, structured answers; Design S6 - comparison addendum | I12: Primary: P4 System behavior. Supporting: P5 Retrieval approach; P7 Evaluation evidence. | L12: Blocking | M12: Harness: chat window | N12: Carried from v3 | O12: Per-paper structure with both papers cited | P12: P4 | Q12: P5 P7
A13: TC-012 | B13: Cross-paper comparison | C13: Compare self-repair in code generation with the counterfeit conundrum: what does each paper conclude? | D13: Answer separately states each paper's conclusion (self-repair: inconsistent benefit; counterfeit conundrum: models struggle to distinguish correct from superficially similar incorrect code), citing iclr_OlaussonIW0S24 and acl_GuLJOLSS24. | G13: Pass: both papers cited, conclusions attributed correctly to the right paper, not swapped. Fail: conclusions mixed up between papers or one paper omitted. | H13: Spec S6.2 - cross-paper comparison | I13: Primary: P4 System behavior. Supporting: P5 Retrieval approach. | L13: Should-fix | M13: Harness: chat window | N13: Carried from v3 | O13: Comparison answer with both papers cited | P13: P4 | Q13: P5
... A153: TC-157 | B153: Trend / change over time | C153: How did program synthesis research change from 2005 to 2020? | D153: Treated as a change-over-time question: the answer is ordered oldest first, each period cites a paper that was retrieved, every year given belongs to the cited paper, and thin coverage is stated when it applies. | G153: Pass: chronological order, each bullet cited and dated by the cited paper, no invented period. Fail: a single-paper answer that ignores the range, a timeline with an uncited period, or years that do not match the cited papers. | H153: Spec 6.3; code review run 3 finding on trend wording (TC-136) | I153: Primary: P4 System behavior. Supporting: P6 Workflow; P5 Retrieval approach. | L153: Should-fix | M153: Harness: chat window | N153: New in v4 | O153: Change phrased as 'change from X to Y' | P153: P4 | Q153: P6 P5

Sheet Rubric Coverage
A1: Rubric coverage: the parts of the 8.1 'Complete' rating that the system itself can show, traced to test cases
A2: The 8.1 rubric has one 1-point criterion (Complete or Incomplete; Incomplete means two or more required elements are missing). This workbook covers 15 parameters that can be shown by running the system. The presentation, README text, file upload and link-sharing parameters are listed below the table as yours. Counts and status update from the Test Result column on the Test Cases sheet.
A4: Code | B4: Group | C4: Parameter | D4: What the rubric or assignment requires | E4: How it is evidenced | F4: Primary cases | G4: Supporting cases | H4: Primary passed | I4: Primary failed | J4: Primary not yet run | K4: Status | L4: Primary case IDs
A5: P3 | B5: System behaviour shown by the tests | C5: System architecture | D5: Rubric: 'the system architecture'. LO1: present the architecture. | E5: Scripted checks that every architecture component exists as a named function or class, that the prompt keeps its trust boundaries, and that a traced question passes the stages in the designed order. | F5: =COUNTIF('Rubric Matrix'!D$2:D$153,"P") -> 2 | G5: =COUNTIF('Rubric Matrix'!D$2:D$153,"S") -> 8 | H5: =COUNTIFS('Rubric Matrix'!D$2:D$153,"P",'Rubric Matrix'!$C$2:$C$153,"Pass")+COUNTIFS('Rubric Matrix'!D$2:D$153,"P",'Rubric Matrix'!$C$2:$C$153,"Accepted limitation") -> 0 | I5: =COUNTIFS('Rubric Matrix'!D$2:D$153,"P",'Rubric Matrix'!$C$2:$C$153,"Fail") -> 0 | J5: =F5-H5-I5 -> 2 | K5: =IF(F5=0,"No coverage",IF(G5=0,"No supporting case",IF(I5>0,"At risk",IF(H5=F5,"Evidenced","Not yet evidenced")))) -> Not yet evidenced | L5: TC-132, TC-154
A6: P4 | B6: System behaviour shown by the tests | C6: System behavior | D6: Rubric: 'behavior'. Assignment: 'How your system works'. LO1: present the behavior. | E6: Real answers, refusals and follow-ups captured by the harness in the Actual Result column. | F6: =COUNTIF('Rubric Matrix'!E$2:E$153,"P") -> 55 | G6: =COUNTIF('Rubric Matrix'!E$2:E$153,"S") -> 31 | H6: =COUNTIFS('Rubric Matrix'!E$2:E$153,"P",'Rubric Matrix'!$C$2:$C$153,"Pass")+COUNTIFS('Rubric Matrix'!E$2:E$153,"P",'Rubric Matrix'!$C$2:$C$153,"Accepted limitation") -> 0 | I6: =COUNTIFS('Rubric Matrix'!E$2:E$153,"P",'Rubric Matrix'!$C$2:$C$153,"Fail") -> 0 | J6: =F6-H6-I6 -> 55 | K6: =IF(F6=0,"No coverage",IF(G6=0,"No supporting case",IF(I6>0,"At risk",IF(H6=F6,"Evidenced","Not yet evidenced")))) -> Not yet evidenced | L6: TC-006, TC-008, TC-009, TC-010, TC-011, TC-012, TC-013, TC-014, TC-017, TC-018, TC-019, TC-020, TC-021, TC-022, TC-023, TC-025, TC-026, TC-028, TC-029, TC-030, TC-031, TC-032, TC-034, TC-043, TC-051, TC-052, TC-053, TC-055, TC-059, TC-060, TC-061, TC-062, TC-063, TC-064, TC-067, TC-068, TC-075, TC-076, TC-084, TC-085, TC-086, TC-087, TC-088, TC-089, TC-094, TC-108, TC-109, TC-111, TC-112, TC-143, TC-144, TC-149, TC-150, TC-151, TC-157
A7: P5 | B7: System behaviour shown by the tests | C7: Retrieval approach | D7: Rubric: 'retrieval approach'. | E7: Chunk size, step, per-paper cap, volume handling and router constants checked against the code; retrieval hits and misses recorded per question. | F7: =COUNTIF('Rubric Matrix'!F$2:F$153,"P") -> 18 | G7: =COUNTIF('Rubric Matrix'!F$2:F$153,"S") -> 22 | H7: =COUNTIFS('Rubric Matrix'!F$2:F$153,"P",'Rubric Matrix'!$C$2:$C$153,"Pass")+COUNTIFS('Rubric Matrix'!F$2:F$153,"P",'Rubric Matrix'!$C$2:$C$153,"Accepted limitation") -> 0 | I7: =COUNTIFS('Rubric Matrix'!F$2:F$153,"P",'Rubric Matrix'!$C$2:$C$153,"Fail") -> 0 | J7: =F7-H7-I7 -> 18 | K7: =IF(F7=0,"No coverage",IF(G7=0,"No supporting case",IF(I7>0,"At risk",IF(H7=F7,"Evidenced","Not yet evidenced")))) -> Not yet evidenced | L7: TC-001, TC-002, TC-003, TC-004, TC-005, TC-015, TC-054, TC-057, TC-058, TC-077, TC-078, TC-079, TC-080, TC-083, TC-133, TC-134, TC-140, TC-141
A8: P6 | B8: System behaviour shown by the tests | C8: Workflow | D8: Rubric: 'workflow'. | E8: Traced route and stage order for a single-topic and a comparison question; intent, follow-up and Sources rules checked one by one. | F8: =COUNTIF('Rubric Matrix'!G$2:G$153,"P") -> 7 | G8: =COUNTIF('Rubric Matrix'!G$2:G$153,"S") -> 25 | H8: =COUNTIFS('Rubric Matrix'!G$2:G$153,"P",'Rubric Matrix'!$C$2:$C$153,"Pass")+COUNTIFS('Rubric Matrix'!G$2:G$153,"P",'Rubric Matrix'!$C$2:$C$153,"Accepted limitation") -> 0 | I8: =COUNTIFS('Rubric Matrix'!G$2:G$153,"P",'Rubric Matrix'!$C$2:$C$153,"Fail") -> 0 | J8: =F8-H8-I8 -> 7 | K8: =IF(F8=0,"No coverage",IF(G8=0,"No supporting case",IF(I8>0,"At risk",IF(H8=F8,"Evidenced","Not yet evidenced")))) -> Not yet evidenced | L8: TC-093, TC-119, TC-136, TC-145, TC-148, TC-153, TC-155
A9: P7 | B9: System behaviour shown by the tests | C9: Evaluation evidence | D9: Rubric: 'evaluation evidence'. Assignment: 'How you evaluated its performance'. LO1: present evaluation results. | E9: Benchmark, conv-check, scorer negative controls, quote checks and the corpus baseline, all produced by the harness and logged. | F9: =COUNTIF('Rubric Matrix'!H$2:H$153,"P") -> 8 | G9: =COUNTIF('Rubric Matrix'!H$2:H$153,"S") -> 34 | H9: =COUNTIFS('Rubric Matrix'!H$2:H$153,"P",'Rubric Matrix'!$C$2:$C$153,"Pass")+COUNTIFS('Rubric Matrix'!H$2:H$153,"P",'Rubric Matrix'!$C$2:$C$153,"Accepted limitation") -> 0 | I9: =COUNTIFS('Rubric Matrix'!H$2:H$153,"P",'Rubric Matrix'!$C$2:$C$153,"Fail") -> 0 | J9: =F9-H9-I9 -> 8 | K9: =IF(F9=0,"No coverage",IF(G9=0,"No supporting case",IF(I9>0,"At risk",IF(H9=F9,"Evidenced","Not yet evidenced")))) -> Not yet evidenced | L9: TC-027, TC-033, TC-050, TC-069, TC-072, TC-073, TC-092, TC-147
A10: P8 | B10: System behaviour shown by the tests | C10: Key engineering decisions | D10: Rubric: 'engineering decisions'. Assignment: 'Why you made key engineering decisions'. LO2. | E10: Each design decision has a test that exercises it: heuristic router, two-model split, content-based years, duplicate collapse, citations resolved after the answer, bounded history. | F10: =COUNTIF('Rubric Matrix'!I$2:I$153,"P") -> 5 | G10: =COUNTIF('Rubric Matrix'!I$2:I$153,"S") -> 30 | H10: =COUNTIFS('Rubric Matrix'!I$2:I$153,"P",'Rubric Matrix'!$C$2:$C$153,"Pass")+COUNTIFS('Rubric Matrix'!I$2:I$153,"P",'Rubric Matrix'!$C$2:$C$153,"Accepted limitation") -> 0 | I10: =COUNTIFS('Rubric Matrix'!I$2:I$153,"P",'Rubric Matrix'!$C$2:$C$153,"Fail") -> 0 | J10: =F10-H10-I10 -> 5 | K10: =IF(F10=0,"No coverage",IF(G10=0,"No supporting case",IF(I10>0,"At risk",IF(H10=F10,"Evidenced","Not yet evidenced")))) -> Not yet evidenced | L10: TC-106, TC-135, TC-138, TC-139, TC-156
A11: P9a | B11: System behaviour shown by the tests | C11: Trade-offs: retrieval strategies | D11: Rubric: 'trade-offs'. LO2: trade-offs among retrieval strategies. | E11: Lexical BM25 versus embeddings and heuristic router versus classifier, each with observed behavior. | F11: =COUNTIF('Rubric Matrix'!J$2:J$153,"P") -> 3 | G11: =COUNTIF('Rubric Matrix'!J$2:J$153,"S") -> 13 | H11: =COUNTIFS('Rubric Matrix'!J$2:J$153,"P",'Rubric Matrix'!$C$2:$C$153,"Pass")+COUNTIFS('Rubric Matrix'!J$2:J$153,"P",'Rubric Matrix'!$C$2:$C$153,"Accepted limitation") -> 0 | I11: =COUNTIFS('Rubric Matrix'!J$2:J$153,"P",'Rubric Matrix'!$C$2:$C$153,"Fail") -> 0 | J11: =F11-H11-I11 -> 3 | K11: =IF(F11=0,"No coverage",IF(G11=0,"No supporting case",IF(I11>0,"At risk",IF(H11=F11,"Evidenced","Not yet evidenced")))) -> Not yet evidenced | L11: TC-007, TC-016, TC-081
A12: P9b | B12: System behaviour shown by the tests | C12: Trade-offs: evaluation approaches | D12: LO2: trade-offs among evaluation approaches. | E12: Negative controls show that the term-match, source-hit and quote checks can fail; what each can and cannot detect. | F12: =COUNTIF('Rubric Matrix'!K$2:K$153,"P") -> 3 | G12: =COUNTIF('Rubric Matrix'!K$2:K$153,"S") -> 8 | H12: =COUNTIFS('Rubric Matrix'!K$2:K$153,"P",'Rubric Matrix'!$C$2:$C$153,"Pass")+COUNTIFS('Rubric Matrix'!K$2:K$153,"P",'Rubric Matrix'!$C$2:$C$153,"Accepted limitation") -> 0 | I12: =COUNTIFS('Rubric Matrix'!K$2:K$153,"P",'Rubric Matrix'!$C$2:$C$153,"Fail") -> 0 | J12: =F12-H12-I12 -> 3 | K12: =IF(F12=0,"No coverage",IF(G12=0,"No supporting case",IF(I12>0,"At risk",IF(H12=F12,"Evidenced","Not yet evidenced")))) -> Not yet evidenced | L12: TC-095, TC-116, TC-117
A13: P9c | B13: System behaviour shown by the tests | C13: Trade-offs: security | D13: LO2: trade-offs among security. | E13: Layered defence versus false positives and known gaps, shown with probe results. | F13: =COUNTIF('Rubric Matrix'!L$2:L$153,"P") -> 19 | G13: =COUNTIF('Rubric Matrix'!L$2:L$153,"S") -> 6 | H13: =COUNTIFS('Rubric Matrix'!L$2:L$153,"P",'Rubric Matrix'!$C$2:$C$153,"Pass")+COUNTIFS('Rubric Matrix'!L$2:L$153,"P",'Rubric Matrix'!$C$2:$C$153,"Accepted limitation") -> 0 | I13: =COUNTIFS('Rubric Matrix'!L$2:L$153,"P",'Rubric Matrix'!$C$2:$C$153,"Fail") -> 0 | J13: =F13-H13-I13 -> 19 | K13: =IF(F13=0,"No coverage",IF(G13=0,"No supporting case",IF(I13>0,"At risk",IF(H13=F13,"Evidenced","Not yet evidenced")))) -> Not yet evidenced | L13: TC-035, TC-036, TC-037, TC-038, TC-039, TC-040, TC-041, TC-042, TC-070, TC-096, TC-097, TC-098, TC-099, TC-100, TC-101, TC-102, TC-103, TC-118, TC-142
A14: P9d | B14: System behaviour shown by the tests | C14: Trade-offs: performance and cost | D14: LO2: trade-offs among performance. | E14: Cache, router, history budget and two-model split versus correctness risk, shown with token and latency numbers. | F14: =COUNTIF('Rubric Matrix'!M$2:M$153,"P") -> 12 | G14: =COUNTIF('Rubric Matrix'!M$2:M$153,"S") -> 9 | H14: =COUNTIFS('Rubric Matrix'!M$2:M$153,"P",'Rubric Matrix'!$C$2:$C$153,"Pass")+COUNTIFS('Rubric Matrix'!M$2:M$153,"P",'Rubric Matrix'!$C$2:$C$153,"Accepted limitation") -> 0 | I14: =COUNTIFS('Rubric Matrix'!M$2:M$153,"P",'Rubric Matrix'!$C$2:$C$153,"Fail") -> 0 | J14: =F14-H14-I14 -> 12 | K14: =IF(F14=0,"No coverage",IF(G14=0,"No supporting case",IF(I14>0,"At risk",IF(H14=F14,"Evidenced","Not yet evidenced")))) -> Not yet evidenced | L14: TC-044, TC-045, TC-046, TC-047, TC-048, TC-049, TC-104, TC-105, TC-113, TC-137, TC-146, TC-152
A15: P9e | B15: System behaviour shown by the tests | C15: Trade-offs: operational considerations | D15: LO2: trade-offs among operational considerations. | E15: Configuration errors, model failure, missing corpus, cache start-up and single-process limits. | F15: =COUNTIF('Rubric Matrix'!N$2:N$153,"P") -> 8 | G15: =COUNTIF('Rubric Matrix'!N$2:N$153,"S") -> 11 | H15: =COUNTIFS('Rubric Matrix'!N$2:N$153,"P",'Rubric Matrix'!$C$2:$C$153,"Pass")+COUNTIFS('Rubric Matrix'!N$2:N$153,"P",'Rubric Matrix'!$C$2:$C$153,"Accepted limitation") -> 0 | I15: =COUNTIFS('Rubric Matrix'!N$2:N$153,"P",'Rubric Matrix'!$C$2:$C$153,"Fail") -> 0 | J15: =F15-H15-I15 -> 8 | K15: =IF(F15=0,"No coverage",IF(G15=0,"No supporting case",IF(I15>0,"At risk",IF(H15=F15,"Evidenced","Not yet evidenced")))) -> Not yet evidenced | L15: TC-056, TC-066, TC-082, TC-115, TC-120, TC-121, TC-122, TC-123
A16: P10 | B16: System behaviour shown by the tests | C16: Remaining limitations | D16: Rubric: 'remaining limitations'. Assignment: 'limitations of your current system'. | E16: Cases that record a limitation with the observed behavior (undated papers, counting across the collection, no persistence, paraphrase misses). | F16: =COUNTIF('Rubric Matrix'!O$2:O$153,"P") -> 4 | G16: =COUNTIF('Rubric Matrix'!O$2:O$153,"S") -> 27 | H16: =COUNTIFS('Rubric Matrix'!O$2:O$153,"P",'Rubric Matrix'!$C$2:$C$153,"Pass")+COUNTIFS('Rubric Matrix'!O$2:O$153,"P",'Rubric Matrix'!$C$2:$C$153,"Accepted limitation") -> 0 | I16: =COUNTIFS('Rubric Matrix'!O$2:O$153,"P",'Rubric Matrix'!$C$2:$C$153,"Fail") -> 0 | J16: =F16-H16-I16 -> 4 | K16: =IF(F16=0,"No coverage",IF(G16=0,"No supporting case",IF(I16>0,"At risk",IF(H16=F16,"Evidenced","Not yet evidenced")))) -> Not yet evidenced | L16: TC-024, TC-090, TC-091, TC-110
A17: G1 | B17: Working implementation and setup | C17: Working implementation and source code | D17: Rubric: repository 'containing the working implementation'. Assignment: 'The source code for your system'. | E17: File compiles and imports without side effects; every start mode runs; an unknown mode gives a usage message. | F17: =COUNTIF('Rubric Matrix'!P$2:P$153,"P") -> 4 | G17: =COUNTIF('Rubric Matrix'!P$2:P$153,"S") -> 4 | H17: =COUNTIFS('Rubric Matrix'!P$2:P$153,"P",'Rubric Matrix'!$C$2:$C$153,"Pass")+COUNTIFS('Rubric Matrix'!P$2:P$153,"P",'Rubric Matrix'!$C$2:$C$153,"Accepted limitation") -> 0 | I17: =COUNTIFS('Rubric Matrix'!P$2:P$153,"P",'Rubric Matrix'!$C$2:$C$153,"Fail") -> 0 | J17: =F17-H17-I17 -> 4 | K17: =IF(F17=0,"No coverage",IF(G17=0,"No supporting case",IF(I17>0,"At risk",IF(H17=F17,"Evidenced","Not yet evidenced")))) -> Not yet evidenced | L17: TC-124, TC-125, TC-128, TC-129
A18: G4 | B18: Working implementation and setup | C18: Dependencies, environment variables, setup | D18: Assignment: 'any required dependencies, environment variables, or setup instructions'. | E18: Requirements file covers every import; the code reads exactly the six documented variables; bad configuration is reported without printing key values. | F18: =COUNTIF('Rubric Matrix'!Q$2:Q$153,"P") -> 2 | G18: =COUNTIF('Rubric Matrix'!Q$2:Q$153,"S") -> 3 | H18: =COUNTIFS('Rubric Matrix'!Q$2:Q$153,"P",'Rubric Matrix'!$C$2:$C$153,"Pass")+COUNTIFS('Rubric Matrix'!Q$2:Q$153,"P",'Rubric Matrix'!$C$2:$C$153,"Accepted limitation") -> 0 | I18: =COUNTIFS('Rubric Matrix'!Q$2:Q$153,"P",'Rubric Matrix'!$C$2:$C$153,"Fail") -> 0 | J18: =F18-H18-I18 -> 2 | K18: =IF(F18=0,"No coverage",IF(G18=0,"No supporting case",IF(I18>0,"At risk",IF(H18=F18,"Evidenced","Not yet evidenced")))) -> Not yet evidenced | L18: TC-126, TC-130
A19: S2 | B19: Credential hygiene | C19: No credentials in source or generated evidence | D19: Submission details: repository 'does not contain sensitive credentials'. | E19: Scan of the project folder and of every harness output (logs, workbook) for key patterns and configured key values. | F19: =COUNTIF('Rubric Matrix'!R$2:R$153,"P") -> 2 | G19: =COUNTIF('Rubric Matrix'!R$2:R$153,"S") -> 3 | H19: =COUNTIFS('Rubric Matrix'!R$2:R$153,"P",'Rubric Matrix'!$C$2:$C$153,"Pass")+COUNTIFS('Rubric Matrix'!R$2:R$153,"P",'Rubric Matrix'!$C$2:$C$153,"Accepted limitation") -> 0 | I19: =COUNTIFS('Rubric Matrix'!R$2:R$153,"P",'Rubric Matrix'!$C$2:$C$153,"Fail") -> 0 | J19: =F19-H19-I19 -> 2 | K19: =IF(F19=0,"No coverage",IF(G19=0,"No supporting case",IF(I19>0,"At risk",IF(H19=F19,"Evidenced","Not yet evidenced")))) -> Not yet evidenced | L19: TC-127, TC-131
C21: Parameters evidenced | D21: =COUNTIF(K5:K19,"Evidenced")&" of "&COUNTA(A5:A19) -> 0 of 15
C22: Parameters at risk | D22: =COUNTIF(K5:K19,"At risk") -> 0
C23: Parameters not yet evidenced | D23: =COUNTIF(K5:K19,"Not yet evidenced") -> 15
C24: Reading | D24: =IF(D22=0,IF(COUNTIF(K5:K19,"Evidenced")=COUNTA(A5:A19),"All covered parameters evidenced by the tests","Not yet: resolve parameters not yet evidenced"),"Not yet: "&D22&" parameter(s) at risk. The rubric rates a submission Incomplete when two or more required elements are missing.") -> Not yet: resolve parameters not yet evidenced
A26: Left to you (not tested in this workbook)
A27: Code | C27: Parameter | D27: Where it lives
A28: P1 | C28: Problem the system solves | D28: Recorded presentation
A29: P2 | C29: Intended use case | D29: Recorded presentation
A30: P11 | C30: Future improvements | D30: Recorded presentation
A31: P12 | C31: Lessons learned | D31: Recorded presentation
A32: G2 | C32: README: purpose | D32: GitHub repository (README text)
A33: G3 | C33: README: install, configure and run | D33: GitHub repository (README text, walkthrough on a clean machine)
A34: G5 | C34: README: known limitations for reviewers | D34: GitHub repository (README text)
A35: G6 | C35: Supporting files for the demonstrated functionality | D35: GitHub repository (files you choose to upload)
A36: S1 | C36: Recording link shareable | D36: Submission package (upload and sharing)
A37: S2 (access and history) | C37: Repository access for the Learning Facilitator; credential scan of git history | D37: Submission package (upload and sharing)

Sheet Rubric Matrix
A1: Test Case ID | B1: Category | C1: Result | D1: P3 | E1: P4 | F1: P5 | G1: P6 | H1: P7 | I1: P8 | J1: P9a | K1: P9b | L1: P9c | M1: P9d | N1: P9e | O1: P10 | P1: G1 | Q1: G4 | R1: S2
A2: ='Test Cases'!A2 -> TC-001 | B2: ='Test Cases'!B2 -> Individual-paper retrieval | C2: =IF('Test Cases'!F2="","",'Test Cases'!F2) | E2: S | F2: P | G2: S | H2: S
A3: ='Test Cases'!A3 -> TC-002 | B3: ='Test Cases'!B3 -> Individual-paper retrieval | C3: =IF('Test Cases'!F3="","",'Test Cases'!F3) | E3: S | F3: P | H3: S
A4: ='Test Cases'!A4 -> TC-003 | B4: ='Test Cases'!B4 -> Individual-paper retrieval | C4: =IF('Test Cases'!F4="","",'Test Cases'!F4) | F4: P | H4: S
A5: ='Test Cases'!A5 -> TC-004 | B5: ='Test Cases'!B5 -> Individual-paper retrieval | C5: =IF('Test Cases'!F5="","",'Test Cases'!F5) | F5: P | H5: S
A6: ='Test Cases'!A6 -> TC-005 | B6: ='Test Cases'!B6 -> Individual-paper retrieval | C6: =IF('Test Cases'!F6="","",'Test Cases'!F6) | F6: P | H6: S
A7: ='Test Cases'!A7 -> TC-006 | B7: ='Test Cases'!B7 -> Individual-paper retrieval | C7: =IF('Test Cases'!F7="","",'Test Cases'!F7) | E7: P | F7: S | H7: S
A8: ='Test Cases'!A8 -> TC-007 | B8: ='Test Cases'!B8 -> Individual-paper retrieval | C8: =IF('Test Cases'!F8="","",'Test Cases'!F8) | F8: S | H8: S | J8: P
A9: ='Test Cases'!A9 -> TC-008 | B9: ='Test Cases'!B9 -> Individual-paper retrieval | C9: =IF('Test Cases'!F9="","",'Test Cases'!F9) | E9: P | F9: S
A10: ='Test Cases'!A10 -> TC-009 | B10: ='Test Cases'!B10 -> Individual-paper retrieval | C10: =IF('Test Cases'!F10="","",'Test Cases'!F10) | E10: P | H10: S | O10: S
A11: ='Test Cases'!A11 -> TC-010 | B11: ='Test Cases'!B11 -> Individual-paper retrieval | C11: =IF('Test Cases'!F11="","",'Test Cases'!F11) | E11: P | N11: S
A12: ='Test Cases'!A12 -> TC-011 | B12: ='Test Cases'!B12 -> Cross-paper comparison | C12: =IF('Test Cases'!F12="","",'Test Cases'!F12) | E12: P | F12: S | H12: S
A13: ='Test Cases'!A13 -> TC-012 | B13: ='Test Cases'!B13 -> Cross-paper comparison | C13: =IF('Test Cases'!F13="","",'Test Cases'!F13) | E13: P | F13: S
A14: ='Test Cases'!A14 -> TC-013 | B14: ='Test Cases'!B14 -> Cross-paper comparison | C14: =IF('Test Cases'!F14="","",'Test Cases'!F14) | E14: P | F14: S
A15: ='Test Cases'!A15 -> TC-014 | B15: ='Test Cases'!B15 -> Cross-paper comparison | C15: =IF('Test Cases'!F15="","",'Test Cases'!F15) | E15: P | F15: S
A16: ='Test Cases'!A16 -> TC-015 | B16: ='Test Cases'!B16 -> Cross-paper comparison | C16: =IF('Test Cases'!F16="","",'Test Cases'!F16) | F16: P | J16: S
A17: ='Test Cases'!A17 -> TC-016 | B17: ='Test Cases'!B17 -> Cross-paper comparison | C17: =IF('Test Cases'!F17="","",'Test Cases'!F17) | F17: S | J17: P | O17: S
A18: ='Test Cases'!A18 -> TC-017 | B18: ='Test Cases'!B18 -> Cross-paper comparison | C18: =IF('Test Cases'!F18="","",'Test Cases'!F18) | E18: P | I18: S | O18: S
A19: ='Test Cases'!A19 -> TC-018 | B19: ='Test Cases'!B19 -> Cross-paper comparison | C19: =IF('Test Cases'!F19="","",'Test Cases'!F19) | E19: P | I19: S
A20: ='Test Cases'!A20 -> TC-019 | B20: ='Test Cases'!B20 -> Trend / change over time | C20: =IF('Test Cases'!F20="","",'Test Cases'!F20) | E20: P | G20: S | H20: S
A21: ='Test Cases'!A21 -> TC-020 | B21: ='Test Cases'!B21 -> Trend / change over time | C21: =IF('Test Cases'!F21="","",'Test Cases'!F21) | E21: P | H21: S
A22: ='Test Cases'!A22 -> TC-021 | B22: ='Test Cases'!B22 -> Trend / change over time | C22: =IF('Test Cases'!F22="","",'Test Cases'!F22) | E22: P | H22: S
A23: ='Test Cases'!A23 -> TC-022 | B23: ='Test Cases'!B23 -> Trend / change over time | C23: =IF('Test Cases'!F23="","",'Test Cases'!F23) | E23: P | O23: S
A24: ='Test Cases'!A24 -> TC-023 | B24: ='Test Cases'!B24 -> Trend / change over time | C24: =IF('Test Cases'!F24="","",'Test Cases'!F24) | E24: P | H24: S
A25: ='Test Cases'!A25 -> TC-024 | B25: ='Test Cases'!B25 -> Trend / change over time | C25: =IF('Test Cases'!F25="","",'Test Cases'!F25) | E25: S | O25: P
A26: ='Test Cases'!A26 -> TC-025 | B26: ='Test Cases'!B26 -> Trend / change over time | C26: =IF('Test Cases'!F26="","",'Test Cases'!F26) | E26: P | G26: S | O26: S
A27: ='Test Cases'!A27 -> TC-026 | B27: ='Test Cases'!B27 -> Trend / change over time | C27: =IF('Test Cases'!F27="","",'Test Cases'!F27) | E27: P | G27: S
A28: ='Test Cases'!A28 -> TC-027 | B28: ='Test Cases'!B28 -> Grounding and citation | C28: =IF('Test Cases'!F28="","",'Test Cases'!F28) | E28: S | H28: P | K28: S
A29: ='Test Cases'!A29 -> TC-028 | B29: ='Test Cases'!B29 -> Grounding and citation | C29: =IF('Test Cases'!F29="","",'Test Cases'!F29) | E29: P | G29: S
A30: ='Test Cases'!A30 -> TC-029 | B30: ='Test Cases'!B30 -> Grounding and citation | C30: =IF('Test Cases'!F30="","",'Test Cases'!F30) | E30: P | H30: S
A31: ='Test Cases'!A31 -> TC-030 | B31: ='Test Cases'!B31 -> Grounding and citation | C31: =IF('Test Cases'!F31="","",'Test Cases'!F31) | E31: P | G31: S
A32: ='Test Cases'!A32 -> TC-031 | B32: ='Test Cases'!B32 -> Grounding and citation | C32: =IF('Test Cases'!F32="","",'Test Cases'!F32) | E32: P | G32: S
A33: ='Test Cases'!A33 -> TC-032 | B33: ='Test Cases'!B33 -> Grounding and citation | C33: =IF('Test Cases'!F33="","",'Test Cases'!F33) | E33: P | N33: S
A34: ='Test Cases'!A34 -> TC-033 | B34: ='Test Cases'!B34 -> Grounding and citation | C34: =IF('Test Cases'!F34="","",'Test Cases'!F34) | E34: S | H34: P
A35: ='Test Cases'!A35 -> TC-034 | B35: ='Test Cases'!B35 -> Grounding and citation | C35: =IF('Test Cases'!F35="","",'Test Cases'!F35) | E35: P | O35: S
A36: ='Test Cases'!A36 -> TC-035 | B36: ='Test Cases'!B36 -> Security and adversarial | C36: =IF('Test Cases'!F36="","",'Test Cases'!F36) | H36: S | I36: S | L36: P
A37: ='Test Cases'!A37 -> TC-036 | B37: ='Test Cases'!B37 -> Security and adversarial | C37: =IF('Test Cases'!F37="","",'Test Cases'!F37) | H37: S | I37: S | L37: P
A38: ='Test Cases'!A38 -> TC-037 | B38: ='Test Cases'!B38 -> Security and adversarial | C38: =IF('Test Cases'!F38="","",'Test Cases'!F38) | H38: S | L38: P
A39: ='Test Cases'!A39 -> TC-038 | B39: ='Test Cases'!B39 -> Security and adversarial | C39: =IF('Test Cases'!F39="","",'Test Cases'!F39) | D39: S | I39: S | L39: P
A40: ='Test Cases'!A40 -> TC-039 | B40: ='Test Cases'!B40 -> Security and adversarial | C40: =IF('Test Cases'!F40="","",'Test Cases'!F40) | H40: S | L40: P
...

Sheet Summary
A1: Test run summary
A3: Result | B3: Count
A4: Pass | B4: =COUNTIF('Test Cases'!$F$2:$F$153,"Pass") -> 0
A5: Fail | B5: =COUNTIF('Test Cases'!$F$2:$F$153,"Fail") -> 0
A6: Blocked | B6: =COUNTIF('Test Cases'!$F$2:$F$153,"Blocked") -> 0
A7: Accepted limitation | B7: =COUNTIF('Test Cases'!$F$2:$F$153,"Accepted limitation") -> 0
A8: Not Run | B8: =COUNTIF('Test Cases'!$F$2:$F$153,"Not Run")+COUNTBLANK('Test Cases'!$F$2:$F$153) -> 152
A9: Total cases | B9: =SUM(B4:B8) -> 152
A10: Pass rate of cases run | B10: =IF(B9-B8=0,"",B4/(B9-B8))
A12: Category | B12: Cases | C12: Pass | D12: Fail | E12: Blocked | F12: Accepted limitation | G12: Not Run
A13: Individual-paper retrieval | B13: =COUNTIF('Test Cases'!$B$2:$B$153,A13) -> 20 | C13: =COUNTIFS('Test Cases'!$B$2:$B$153,$A13,'Test Cases'!$F$2:$F$153,"Pass") -> 0 | D13: =COUNTIFS('Test Cases'!$B$2:$B$153,$A13,'Test Cases'!$F$2:$F$153,"Fail") -> 0 | E13: =COUNTIFS('Test Cases'!$B$2:$B$153,$A13,'Test Cases'!$F$2:$F$153,"Blocked") -> 0 | F13: =COUNTIFS('Test Cases'!$B$2:$B$153,$A13,'Test Cases'!$F$2:$F$153,"Accepted limitation") -> 0 | G13: =B13-C13-D13-E13-F13 -> 20
A14: Cross-paper comparison | B14: =COUNTIF('Test Cases'!$B$2:$B$153,A14) -> 12 | C14: =COUNTIFS('Test Cases'!$B$2:$B$153,$A14,'Test Cases'!$F$2:$F$153,"Pass") -> 0 | D14: =COUNTIFS('Test Cases'!$B$2:$B$153,$A14,'Test Cases'!$F$2:$F$153,"Fail") -> 0 | E14: =COUNTIFS('Test Cases'!$B$2:$B$153,$A14,'Test Cases'!$F$2:$F$153,"Blocked") -> 0 | F14: =COUNTIFS('Test Cases'!$B$2:$B$153,$A14,'Test Cases'!$F$2:$F$153,"Accepted limitation") -> 0 | G14: =B14-C14-D14-E14-F14 -> 12
A15: Trend / change over time | B15: =COUNTIF('Test Cases'!$B$2:$B$153,A15) -> 17 | C15: =COUNTIFS('Test Cases'!$B$2:$B$153,$A15,'Test Cases'!$F$2:$F$153,"Pass") -> 0 | D15: =COUNTIFS('Test Cases'!$B$2:$B$153,$A15,'Test Cases'!$F$2:$F$153,"Fail") -> 0 | E15: =COUNTIFS('Test Cases'!$B$2:$B$153,$A15,'Test Cases'!$F$2:$F$153,"Blocked") -> 0 | F15: =COUNTIFS('Test Cases'!$B$2:$B$153,$A15,'Test Cases'!$F$2:$F$153,"Accepted limitation") -> 0 | G15: =B15-C15-D15-E15-F15 -> 17
A16: Grounding and citation | B16: =COUNTIF('Test Cases'!$B$2:$B$153,A16) -> 15 | C16: =COUNTIFS('Test Cases'!$B$2:$B$153,$A16,'Test Cases'!$F$2:$F$153,"Pass") -> 0 | D16: =COUNTIFS('Test Cases'!$B$2:$B$153,$A16,'Test Cases'!$F$2:$F$153,"Fail") -> 0 | E16: =COUNTIFS('Test Cases'!$B$2:$B$153,$A16,'Test Cases'!$F$2:$F$153,"Blocked") -> 0 | F16: =COUNTIFS('Test Cases'!$B$2:$B$153,$A16,'Test Cases'!$F$2:$F$153,"Accepted limitation") -> 0 | G16: =B16-C16-D16-E16-F16 -> 15
A17: Security and adversarial | B17: =COUNTIF('Test Cases'!$B$2:$B$153,A17) -> 18 | C17: =COUNTIFS('Test Cases'!$B$2:$B$153,$A17,'Test Cases'!$F$2:$F$153,"Pass") -> 0 | D17: =COUNTIFS('Test Cases'!$B$2:$B$153,$A17,'Test Cases'!$F$2:$F$153,"Fail") -> 0 | E17: =COUNTIFS('Test Cases'!$B$2:$B$153,$A17,'Test Cases'!$F$2:$F$153,"Blocked") -> 0 | F17: =COUNTIFS('Test Cases'!$B$2:$B$153,$A17,'Test Cases'!$F$2:$F$153,"Accepted limitation") -> 0 | G17: =B17-C17-D17-E17-F17 -> 18
A18: Performance and cost | B18: =COUNTIF('Test Cases'!$B$2:$B$153,A18) -> 12 | C18: =COUNTIFS('Test Cases'!$B$2:$B$153,$A18,'Test Cases'!$F$2:$F$153,"Pass") -> 0 | D18: =COUNTIFS('Test Cases'!$B$2:$B$153,$A18,'Test Cases'!$F$2:$F$153,"Fail") -> 0 | E18: =COUNTIFS('Test Cases'!$B$2:$B$153,$A18,'Test Cases'!$F$2:$F$153,"Blocked") -> 0 | F18: =COUNTIFS('Test Cases'!$B$2:$B$153,$A18,'Test Cases'!$F$2:$F$153,"Accepted limitation") -> 0 | G18: =B18-C18-D18-E18-F18 -> 12
A19: Data quality and corpus integrity | B19: =COUNTIF('Test Cases'!$B$2:$B$153,A19) -> 14 | C19: =COUNTIFS('Test Cases'!$B$2:$B$153,$A19,'Test Cases'!$F$2:$F$153,"Pass") -> 0 | D19: =COUNTIFS('Test Cases'!$B$2:$B$153,$A19,'Test Cases'!$F$2:$F$153,"Fail") -> 0 | E19: =COUNTIFS('Test Cases'!$B$2:$B$153,$A19,'Test Cases'!$F$2:$F$153,"Blocked") -> 0 | F19: =COUNTIFS('Test Cases'!$B$2:$B$153,$A19,'Test Cases'!$F$2:$F$153,"Accepted limitation") -> 0 | G19: =B19-C19-D19-E19-F19 -> 14
A20: Conversational usability | B20: =COUNTIF('Test Cases'!$B$2:$B$153,A20) -> 15 | C20: =COUNTIFS('Test Cases'!$B$2:$B$153,$A20,'Test Cases'!$F$2:$F$153,"Pass") -> 0 | D20: =COUNTIFS('Test Cases'!$B$2:$B$153,$A20,'Test Cases'!$F$2:$F$153,"Fail") -> 0 | E20: =COUNTIFS('Test Cases'!$B$2:$B$153,$A20,'Test Cases'!$F$2:$F$153,"Blocked") -> 0 | F20: =COUNTIFS('Test Cases'!$B$2:$B$153,$A20,'Test Cases'!$F$2:$F$153,"Accepted limitation") -> 0 | G20: =B20-C20-D20-E20-F20 -> 15
A21: Regression and acceptance | B21: =COUNTIF('Test Cases'!$B$2:$B$153,A21) -> 7 | C21: =COUNTIFS('Test Cases'!$B$2:$B$153,$A21,'Test Cases'!$F$2:$F$153,"Pass") -> 0 | D21: =COUNTIFS('Test Cases'!$B$2:$B$153,$A21,'Test Cases'!$F$2:$F$153,"Fail") -> 0 | E21: =COUNTIFS('Test Cases'!$B$2:$B$153,$A21,'Test Cases'!$F$2:$F$153,"Blocked") -> 0 | F21: =COUNTIFS('Test Cases'!$B$2:$B$153,$A21,'Test Cases'!$F$2:$F$153,"Accepted limitation") -> 0 | G21: =B21-C21-D21-E21-F21 -> 7
A22: Architecture and workflow verification | B22: =COUNTIF('Test Cases'!$B$2:$B$153,A22) -> 10 | C22: =COUNTIFS('Test Cases'!$B$2:$B$153,$A22,'Test Cases'!$F$2:$F$153,"Pass") -> 0 | D22: =COUNTIFS('Test Cases'!$B$2:$B$153,$A22,'Test Cases'!$F$2:$F$153,"Fail") -> 0 | E22: =COUNTIFS('Test Cases'!$B$2:$B$153,$A22,'Test Cases'!$F$2:$F$153,"Blocked") -> 0 | F22: =COUNTIFS('Test Cases'!$B$2:$B$153,$A22,'Test Cases'!$F$2:$F$153,"Accepted limitation") -> 0 | G22: =B22-C22-D22-E22-F22 -> 10
A23: Operational and configuration | B23: =COUNTIF('Test Cases'!$B$2:$B$153,A23) -> 12 | C23: =COUNTIFS('Test Cases'!$B$2:$B$153,$A23,'Test Cases'!$F$2:$F$153,"Pass") -> 0 | D23: =COUNTIFS('Test Cases'!$B$2:$B$153,$A23,'Test Cases'!$F$2:$F$153,"Fail") -> 0 | E23: =COUNTIFS('Test Cases'!$B$2:$B$153,$A23,'Test Cases'!$F$2:$F$153,"Blocked") -> 0 | F23: =COUNTIFS('Test Cases'!$B$2:$B$153,$A23,'Test Cases'!$F$2:$F$153,"Accepted limitation") -> 0 | G23: =B23-C23-D23-E23-F23 -> 12
A24: Total | B24: =SUM(B13:B23) -> 152 | C24: =SUM(C13:C23) -> 0 | D24: =SUM(D13:D23) -> 0 | E24: =SUM(E13:E23) -> 0 | F24: =SUM(F13:F23) -> 0 | G24: =SUM(G13:G23) -> 152
A26: Severity if failed | B26: Cases | C26: Failed | D26: Not Run
A27: Blocking | B27: =COUNTIF('Test Cases'!$L$2:$L$153,A27) -> 60 | C27: =COUNTIFS('Test Cases'!$L$2:$L$153,A27,'Test Cases'!$F$2:$F$153,"Fail") -> 0 | D27: =COUNTIFS('Test Cases'!$L$2:$L$153,A27,'Test Cases'!$F$2:$F$153,"Not Run")+COUNTIFS('Test Cases'!$L$2:$L$153,A27,'Test Cases'!$F$2:$F$153,"") -> 60
A28: Should-fix | B28: =COUNTIF('Test Cases'!$L$2:$L$153,A28) -> 79 | C28: =COUNTIFS('Test Cases'!$L$2:$L$153,A28,'Test Cases'!$F$2:$F$153,"Fail") -> 0 | D28: =COUNTIFS('Test Cases'!$L$2:$L$153,A28,'Test Cases'!$F$2:$F$153,"Not Run")+COUNTIFS('Test Cases'!$L$2:$L$153,A28,'Test Cases'!$F$2:$F$153,"") -> 79
A29: Noted | B29: =COUNTIF('Test Cases'!$L$2:$L$153,A29) -> 13 | C29: =COUNTIFS('Test Cases'!$L$2:$L$153,A29,'Test Cases'!$F$2:$F$153,"Fail") -> 0 | D29: =COUNTIFS('Test Cases'!$L$2:$L$153,A29,'Test Cases'!$F$2:$F$153,"Not Run")+COUNTIFS('Test Cases'!$L$2:$L$153,A29,'Test Cases'!$F$2:$F$153,"") -> 13
A31: Execution | B31: Cases | C31: Pass | D31: Fail | E31: Not Run
A32: Harness: chat window | B32: =COUNTIF('Test Cases'!$M$2:$M$153,A32) -> 102 | C32: =COUNTIFS('Test Cases'!$M$2:$M$153,A32,'Test Cases'!$F$2:$F$153,"Pass") -> 0 | D32: =COUNTIFS('Test Cases'!$M$2:$M$153,A32,'Test Cases'!$F$2:$F$153,"Fail") -> 0 | E32: =B32-C32-D32-COUNTIFS('Test Cases'!$M$2:$M$153,A32,'Test Cases'!$F$2:$F$153,"Blocked")-COUNTIFS('Test Cases'!$M$2:$M$153,A32,'Test Cases'!$F$2:$F$153,"Accepted limitation") -> 102
A33: Harness: subprocess | B33: =COUNTIF('Test Cases'!$M$2:$M$153,A33) -> 8 | C33: =COUNTIFS('Test Cases'!$M$2:$M$153,A33,'Test Cases'!$F$2:$F$153,"Pass") -> 0 | D33: =COUNTIFS('Test Cases'!$M$2:$M$153,A33,'Test Cases'!$F$2:$F$153,"Fail") -> 0 | E33: =B33-C33-D33-COUNTIFS('Test Cases'!$M$2:$M$153,A33,'Test Cases'!$F$2:$F$153,"Blocked")-COUNTIFS('Test Cases'!$M$2:$M$153,A33,'Test Cases'!$F$2:$F$153,"Accepted limitation") -> 8
A34: Harness: special scenario | B34: =COUNTIF('Test Cases'!$M$2:$M$153,A34) -> 42 | C34: =COUNTIFS('Test Cases'!$M$2:$M$153,A34,'Test Cases'!$F$2:$F$153,"Pass") -> 0 | D34: =COUNTIFS('Test Cases'!$M$2:$M$153,A34,'Test Cases'!$F$2:$F$153,"Fail") -> 0 | E34: =B34-C34-D34-COUNTIFS('Test Cases'!$M$2:$M$153,A34,'Test Cases'!$F$2:$F$153,"Blocked")-COUNTIFS('Test Cases'!$M$2:$M$153,A34,'Test Cases'!$F$2:$F$153,"Accepted limitation") -> 42
A36: Rubric readiness | B36: ='Rubric Coverage'!D21 -> 0 of 15
A37: Rubric reading | B37: ='Rubric Coverage'!D24 -> Not yet: resolve parameters not yet evidenced

Sheet Corpus Facts
A1: Corpus facts behind the expected results
A2: Computed from corpus_text_cache.json and the submission's own year function, and checked against the run-3 answers, so expected results do not rest on assumptions.
A4: Fact | B4: Value | C4: Source or use
A5: Documents loaded | B5: 153 PDF files load; 138 works are indexed after 15 duplicate groups collapse; 18,355,857 characters in the text cache after extraction repair (18,398,803 before; the 42,946 difference is words joined at line ends); 0 unreadable | C5: Test Strategy section 6; TC-072, TC-139
A6: Documents with a resolved year | B6: 151 of 153 files; natosec_40 resolves to 2026 from its arXiv stamp | C6: Submission's own year function (content year first)
A7: Documents with no resolved year | B7: 2: DBLP_conf_pldi_Solar-LezamaATBSS07, DBLP_conf_pldi_Solar-LezamaJB08 | C7: YEAR_OVERRIDES set these to None on purpose (content does not support a date)
A8: Year before 2010 (resolved) | B8: 4 works: DBLP_journals_sttt_Solar-Lezama13 = 2001; DBLP_conf_pldi_Solar-LezamaRBE05 = 2005; DBLP_conf_aplas_2009 = 2009; DBLP_conf_aplas_Solar-Lezama09 = 2009 | C8: TC-025, TC-150. sttt_Solar-Lezama13 is the AES standard (override 2001)
A9: Year after 2020 (resolved) | B9: 59 files by content (2021 or later), 47 distinct works once duplicates and same-title copies collapse (the number the catalog route printed in run 3) | C9: TC-025
A10: Year 2016 (resolved) | B10: 11 files by content, 9 distinct works (sk_p and PolikarpovaYIS16 each exist twice). Not in 2016 any more: conf_icse_JeonQFFS16 (MANTRA, 2026), conf_pldi_KamilCIS16 (Stencil-Lifting, 2025), journals_cacm_WangZKS16 (RVISmith, 2025), journals_ftpl_CheungS16 (2026) | C10: TC-091, TC-143, TC-150
A11: Year 2025 (resolved) | B11: 15 files by content, 13 distinct works. Added by content from a wrong filename year: conf_icra_CamposISK19 (Bench-Push), conf_pldi_KamilCIS16 (Stencil-Lifting), conf_popl_YangYS12 (PICACHV), journals_cacm_WangZKS16 and journals_tocs_WangZKS15 (both RVISmith) | C11: TC-088
A12: Year distribution by content (files) | B12: 2001:1, 2005:1, 2009:2, 2011:3, 2012:11, 2013:3, 2014:5, 2015:10, 2016:11, 2017:13, 2018:15, 2019:9, 2020:8, 2021:12, 2022:7, 2023:3, 2024:12, 2025:15, 2026:10 | C12: Resolved years only (151 files)
A13: Mislabeled: Solar-LezamaATBSS07 | B13: Actually 'BLK-Assist: A Methodological Framework for Artist-Led Co-Creation with Generative AI Models'; year unresolved | C13: Test Strategy section 1; kept on purpose as a negative case; TC-034, TC-051
A14: Mislabeled: Solar-LezamaJB08 | B14: Actually 'Enhance Sketch Recognition's Explainability via Semantic Component-Level Parsing'; year unresolved | C14: Test Strategy section 1; no BENCH credit; TC-052, TC-089
A15: Mislabeled: sttt_Solar-Lezama13 | B15: Actually FIPS 197, Advanced Encryption Standard; year 2001 | C15: Test Strategy section 1; TC-053, TC-109
... A27: Not a mismatch: revised arXiv version | B27: journals_corr_abs-2302-01976 (Sparling, 2023) carries 'to appear at ICLR 2026' on a later revision; the paper is the right one and keeps 2023. Likewise journals_corr_InalaQLS15, journals_corr_PolikarpovaYIS16, conf_ppopp_KurajSP22 and journals_corr_abs-1803-07244 are later arXiv revisions of the correct papers | C27: A date test alone flags these; a first-page title check clears them; TC-138

Sheet Run Guide
A1: Run guide
A3: Purpose | B3: Version 4 of the Research Assistant test cases. It covers the rubric parameters that the running system can show (architecture, behavior, retrieval, workflow, evaluation evidence, decisions, trade-offs, limitations, working implementation, dependencies and configuration, credentials). Presentation, README text, file upload, link sharing and every other step done by hand are left to you and are listed on the Rubric Coverage sheet. Every case here can be run by the harness: 102 by typing into the chat window, 8 as subprocesses and 42 as scripted scenarios.
A4: What changed from v3 | B4: Five manual cases were dropped (TC-065, 071, 074, 107, 114). The manual terminal and dialog cases TC-120 to TC-126 became scripted checks. Four scripted cases from v2 came back (TC-129, 154, 155, 156). 26 cases are new and exercise the run-3 findings one by one (follow-ups, cache key, quote spans, refusal detection, trend gate, catalog boundaries, volume handling, labels, duplicates, content years). Expected results for TC-025, 050, 072, 088, 091 and 119 were corrected. See the Change Log sheet.
A5: Sheets | B5: Test Cases (the sheet the harness reads); Rubric Coverage (15 parameters, counts and status, plus the list of parameters that are yours); Rubric Matrix (case by parameter, P = primary, S = supporting); Corpus Facts (oracle data); Summary; Run Guide; Harness Plans; Change Log.
A6: Columns A to I | B6: Same layout as earlier versions, so Test_Research_Assistant.py reads it unchanged: ID, Category, Test Case, Expected Result, Actual Result (filled by the harness), Test Result (filled by the reviewer), Test Result Criteria, Requirement Traceability, Rubric Mapping.
A7: Columns J to Q | B7: J Test Result Reasoning and K What should be fixed in the code (fill for every Fail); L Severity if failed; M Execution; N Change from v3; O Evidence to capture (what to keep from the run); P and Q the rubric parameter codes.
A8: Test Result values | B8: Pass, Fail, Blocked, Not Run, Accepted limitation. Use Accepted limitation only where the criteria text says to (the paraphrase and counting cases): it counts as evidence and does not put a rubric parameter at risk. TC-099 is Blocked on purpose: the harness never runs it.
A9: Severity | B9: Blocking: a wrong citation, an ungrounded quote reported as grounded, a security probe that passes through the conversational path, a missing dependency, a credential in a file. Should-fix: wrong routing or year miss, fix or disclose. Noted: ergonomics.
A10: Execution | B10: Harness: chat window - the harness types the turns into the real chat window. Harness: subprocess - the harness starts the script (benchmark, conv-check, EOF, start-up in a temporary folder). Harness: special scenario - a scripted function in the harness, with or without a model call (the Test Case text says which). New scenario functions are in Test_Research_Assistant_v4_scenarios.py. Put that file next to the harness and add two lines to the harness before it runs the rows: 'import Test_Research_Assistant_v4_scenarios as v4_scenarios' and 'v4_scenarios.install(globals())'. The Harness Plans sheet lists the PLANS entries it adds. Point the harness at this workbook (v4) instead of v3.
A11: Rubric rule | B11: A parameter is Evidenced only when all of its primary cases are Pass (or Accepted limitation) and at least one supporting case exists. At risk means a primary case failed.
A12: Suggested order | B12: 0) Run the harness self-test. 1) Run the scripted cases that need no model (TC-126 to TC-139, TC-142, TC-145 to TC-152, TC-154, TC-156, TC-120 to TC-125, TC-127 to TC-131); they take seconds and fail fast. 2) Run the chat-window cases. 3) Run the benchmark and conv-check cases (TC-050, TC-069, TC-070, TC-073) as separate executions. 4) Review each transcript against the criteria and fill F, J and K. 5) Read Rubric Coverage.
A13: Heavy cases | B13: TC-050, TC-069, TC-066, TC-070 and TC-073 launch subprocesses and take the longest. TC-123 and TC-124 copy the script into a temporary folder; TC-124 also copies corpus_text_cache.json (about 19 MB).
A14: Independence of evidence | B14: Each case must come from its own execution. TC-050 and TC-073 are separate benchmark runs.
... A16: Not covered | B16: Latency thresholds are recorded rather than judged because no budget exists in the spec. Concurrent users are out of scope (single process). Keyboard Ctrl-C, the Alt+X and Exit button of the chat window, and the configuration dialog are manual and not listed. The optional web front end is not part of this submission.

Sheet Harness Plans
A1: Entries for PLANS in Test_Research_Assistant.py (v4)
A2: Cases whose Test Case text is a plain question need no entry (TC-143, 144, 157). Scripted entries point to functions in Test_Research_Assistant_v4_scenarios.py, which also adds the matching CHECKS entries (chk_script_result) and the SCRIPTS names. Rows already in the run-3 harness are marked 'in run-3 harness'.
A4: Test Case ID | B4: PLANS value (Python) | C4: Status
A5: TC-041 | B5: ("script", "poisoned_retrieval") | C5: in run-3 harness
A6: TC-103 | B6: ("script", "agent_query_sanitization") | C6: in run-3 harness
A7: TC-106 | B7: ("script", "model_role_routing") | C7: in run-3 harness
A8: TC-119 | B8: ("script", "pipeline_trace") | C8: in run-3 harness
A9: TC-120 | B9: ("script", "config_missing_key") | C9: new scenario in the v4 scenarios file
A10: TC-121 | B10: ("script", "config_validation") | C10: new scenario in the v4 scenarios file
A11: TC-122 | B11: ("script", "model_failure_recovery") | C11: new scenario in the v4 scenarios file
A12: TC-123 | B12: ("script", "startup_without_corpus") | C12: new scenario in the v4 scenarios file
A13: TC-124 | B13: ("script", "startup_from_cache") | C13: new scenario in the v4 scenarios file
A14: TC-125 | B14: ("script", "usage_message") | C14: new scenario in the v4 scenarios file
A15: TC-126 | B15: ("script", "requirements_cover_imports") | C15: new scenario in the v4 scenarios file
... A43: TC-156 | B43: ("script", "citation_rewrite") | C43: new scenario in the v4 scenarios file
A45: Changes to existing behavior
A46: PLANS cleanup | B46: Remove the 'manual' entries for TC-065, TC-071 and TC-074 (rows dropped from v4).
A47: TC-119 / pipeline_trace | B47: The required stage order is sanitize, intent, route, retrieval, answer, citation resolution, quote check (design step 6). The run-3 harness required the quote check before citation resolution and reported Fail for correct code. The v4 scenarios file replaces that scenario, so nothing needs editing.
A48: TC-035 check | B48: Add a content check: the reply must contain 'sketch'. The run-3 check passed because no injected word appeared, although the reply was a refusal.
A49: TC-054 check | B49: Add a check that the reply says the two files are the same work and contains no 'journal version' contrast or invented figures.
A50: TC-072 / corpus_stats | B50: Update the recorded baseline to 153 files, 138 works, 18,355,857 characters.
A51: TC-026 check | B51: Assert that the title of the second item of turn 1 appears in turn 2. The run-3 check left F empty.
A52: TC-050 / TC-073 | B52: Compare the BEFORE pass with 1,462,500 tokens (1.25 times the run-3 measurement) and fail when the drift flag line is printed.
A53: Execution column | B53: Rows with an Execution value starting 'Manual' no longer exist in v4. The guard in execute_case can stay.

Sheet Change Log
A1: Changes from v3 (research_assistant_test_case_v3.xlsx, run 3)
A2: Totals: 152 cases in all; 105 carried unchanged, 10 with corrected expectations, 7 rewritten as scripted checks, 30 new or restored. 5 v3 cases dropped.
A4: Case | B4: Change | C4: Why
A5: Scope | B5: Dropped presentation, README, upload and other manual parameters (P1, P2, P11, P12, G2, G3, G5, G6, S1 and the access part of S2). | C5: Those are yours. The 15 parameters left are the ones the running system can show. The Rubric Coverage sheet lists the rest.
A6: TC-065 | B6: Dropped | C6: Ctrl-C at a terminal prompt needs a person at the keyboard.
A7: TC-071 | B7: Dropped | C7: README walkthrough on a clean machine is a manual repository review.
A8: TC-074 | B8: Dropped | C8: Acceptance gate that reviews the presentation; replaced by the Rubric Coverage sheet itself.
A9: TC-107 | B9: Dropped | C9: Recording of benchmark numbers for a slide; the numbers are already produced by TC-050 and TC-073.
A10: TC-114 | B10: Dropped | C10: Alt+X and Exit button need the chat window and a person.
A11: TC-120 | B11: Rewritten as a scripted check | C11: scripted; the v3 version needed the chat window and a changed configuration
A12: TC-121 | B12: Rewritten as a scripted check | C12: scripted; the v3 version needed the configuration dialog
A13: TC-122 | B13: Rewritten as a scripted check | C13: scripted with a failing stub client
A14: TC-123 | B14: Rewritten as a scripted check | C14: scripted in a temporary folder
A15: TC-124 | B15: Rewritten as a scripted check | C15: scripted in a temporary folder; expectation kept (cache alone starts the system), cold rebuild left out
... A59: Wording | B59: Slide, recording and presentation wording removed from kept rows; column O renamed Evidence to capture. | C59: Presentation is out of scope.
